<?xml version="1.0"?>
<robot name="/home/rinaldo/Documents/synthpose-webots/dataset_generator/protos/nao_exported.urdf" xmlns:xacro="http://ros.org/wiki/xacro">
  <link name="base_link">
    <visual>
      <origin xyz="0 0 -0.02" rpy="0 0 0"/>
      <geometry>
        <sphere radius="0.037"/>
      </geometry>
    </visual>
    <collision>
      <origin xyz="0 0 -0.02" rpy="0 0 0"/>
      <geometry>
        <sphere radius="0.037"/>
      </geometry>
    </collision>
    <visual>
      <origin xyz="0 0 0.055" rpy="0 0 0"/>
      <geometry>
        <cylinder radius="0.055" length="0.03"/>
      </geometry>
    </visual>
    <collision>
      <origin xyz="0 0 0.055" rpy="0 0 0"/>
      <geometry>
        <cylinder radius="0.055" length="0.03"/>
      </geometry>
    </collision>
    <visual>
      <origin xyz="0 0.015 0.055" rpy="0 0 0"/>
      <geometry>
        <sphere radius="0.055"/>
      </geometry>
    </visual>
    <collision>
      <origin xyz="0 0.015 0.055" rpy="0 0 0"/>
      <geometry>
        <sphere radius="0.055"/>
      </geometry>
    </collision>
    <visual>
      <origin xyz="0 -0.015 0.055" rpy="0 0 0"/>
      <geometry>
        <sphere radius="0.055"/>
      </geometry>
    </visual>
    <collision>
      <origin xyz="0 -0.015 0.055" rpy="0 0 0"/>
      <geometry>
        <sphere radius="0.055"/>
      </geometry>
    </collision>
  </link>
  <joint name="LHipYawPitch" type="revolute">
    <parent link="base_link"/>
    <child link="LHip"/>
    <axis xyz="0 0.707107 -0.707107"/>
    <limit effort="14.8" lower="-1.14529" upper="0.740718" velocity="4.16174"/>
    <origin xyz="0 0.05 -0.085" rpy="0 -0.000001 0.000001"/>
  </joint>
  <link name="LHip">
  </link>
  <joint name="LHipRoll" type="revolute">
    <parent link="LHip"/>
    <child link="solid"/>
    <axis xyz="1 0 0"/>
    <limit effort="14.8" lower="-0.379435" upper="0.79046" velocity="4.16174"/>
    <origin xyz="0 0 0" rpy="0 0 0"/>
  </joint>
  <link name="solid">
    <visual>
      <origin xyz="-0.017 0 0.004" rpy="0 0 0"/>
      <geometry>
        <box size="0.025 0.025 0.074"/>
      </geometry>
    </visual>
    <collision>
      <origin xyz="-0.017 0 0.004" rpy="0 0 0"/>
      <geometry>
        <box size="0.025 0.025 0.074"/>
      </geometry>
    </collision>
    <visual>
      <origin xyz="-0.018 0 0" rpy="0 0 0"/>
      <geometry>
        <box size="0.08 0.025 0.025"/>
      </geometry>
    </visual>
    <collision>
      <origin xyz="-0.018 0 0" rpy="0 0 0"/>
      <geometry>
        <box size="0.08 0.025 0.025"/>
      </geometry>
    </collision>
  </link>
  <joint name="LHipPitch" type="revolute">
    <parent link="solid"/>
    <child link="solid_0"/>
    <axis xyz="0 1 0"/>
    <limit effort="9.8" lower="-1.77378" upper="0.48398" velocity="6.40239"/>
    <origin xyz="0 0 0" rpy="0 0 0"/>
  </joint>
  <link name="solid_0">
    <visual>
      <origin xyz="-0.009 0 -0.015" rpy="1.570803 -1.047198 -0.000004"/>
      <geometry>
        <cylinder radius="0.03" length="0.01"/>
      </geometry>
    </visual>
    <collision>
      <origin xyz="-0.009 0 -0.015" rpy="1.570803 -1.047198 -0.000004"/>
      <geometry>
        <cylinder radius="0.03" length="0.01"/>
      </geometry>
    </collision>
    <visual>
      <origin xyz="-0.01333 0 -0.0125" rpy="1.570803 -1.047198 -0.000004"/>
      <geometry>
        <sphere radius="0.03"/>
      </geometry>
    </visual>
    <collision>
      <origin xyz="-0.01333 0 -0.0125" rpy="1.570803 -1.047198 -0.000004"/>
      <geometry>
        <sphere radius="0.03"/>
      </geometry>
    </collision>
    <visual>
      <origin xyz="-0.00467 0 -0.0175" rpy="1.570803 -1.047198 -0.000004"/>
      <geometry>
        <sphere radius="0.03"/>
      </geometry>
    </visual>
    <collision>
      <origin xyz="-0.00467 0 -0.0175" rpy="1.570803 -1.047198 -0.000004"/>
      <geometry>
        <sphere radius="0.03"/>
      </geometry>
    </collision>
    <visual>
      <origin xyz="0.008 0 -0.066261" rpy="0 -0.383185 0"/>
      <geometry>
        <cylinder radius="0.035" length="0.1"/>
      </geometry>
    </visual>
    <collision>
      <origin xyz="0.008 0 -0.066261" rpy="0 -0.383185 0"/>
      <geometry>
        <cylinder radius="0.035" length="0.1"/>
      </geometry>
    </collision>
  </link>
  <joint name="LKneePitch" type="revolute">
    <parent link="solid_0"/>
    <child link="solid_1"/>
    <axis xyz="0 1 0"/>
    <limit effort="9.8" lower="-0.0923279" upper="2.11255" velocity="6.40239"/>
    <origin xyz="0 0 -0.1" rpy="0 -0.000001 0"/>
  </joint>
  <link name="solid_1">
    <visual>
      <origin xyz="0.01 0 -0.033" rpy="0 0.462 0"/>
      <geometry>
        <box size="0.04 0.08 0.07"/>
      </geometry>
    </visual>
    <collision>
      <origin xyz="0.01 0 -0.033" rpy="0 0.462 0"/>
      <geometry>
        <box size="0.04 0.08 0.07"/>
      </geometry>
    </collision>
    <visual>
      <origin xyz="0 0.003 -0.09" rpy="1.57 0 0"/>
      <geometry>
        <cylinder radius="0.035" length="0.018"/>
      </geometry>
    </visual>
    <collision>
      <origin xyz="0 0.003 -0.09" rpy="1.57 0 0"/>
      <geometry>
        <cylinder radius="0.035" length="0.018"/>
      </geometry>
    </collision>
    <visual>
      <origin xyz="0 0.003007 -0.081" rpy="1.57 0 0"/>
      <geometry>
        <sphere radius="0.035"/>
      </geometry>
    </visual>
    <collision>
      <origin xyz="0 0.003007 -0.081" rpy="1.57 0 0"/>
      <geometry>
        <sphere radius="0.035"/>
      </geometry>
    </collision>
    <visual>
      <origin xyz="0 0.002993 -0.099" rpy="1.57 0 0"/>
      <geometry>
        <sphere radius="0.035"/>
      </geometry>
    </visual>
    <collision>
      <origin xyz="0 0.002993 -0.099" rpy="1.57 0 0"/>
      <geometry>
        <sphere radius="0.035"/>
      </geometry>
    </collision>
  </link>
  <joint name="LAnklePitch" type="revolute">
    <parent link="solid_1"/>
    <child link="solid_2"/>
    <axis xyz="0 1 0"/>
    <limit effort="9.8" lower="-1.18944" upper="0.922581" velocity="6.40239"/>
    <origin xyz="0 0 -0.1029" rpy="0 -0.000001 0"/>
  </joint>
  <link name="solid_2">
  </link>
  <joint name="LAnkleRoll" type="revolute">
    <parent link="solid_2"/>
    <child link="solid_3"/>
    <axis xyz="1 0 0"/>
    <limit effort="14.8" lower="-0.39788" upper="0.769001" velocity="4.16174"/>
    <origin xyz="0 0 0" rpy="0 0 0"/>
  </joint>
  <link name="solid_3">
    <visual>
      <origin xyz="0.015 0.007 -0.033" rpy="0 0 0"/>
      <geometry>
        <box size="0.11 0.085 0.004"/>
      </geometry>
    </visual>
    <collision>
      <origin xyz="0.015 0.007 -0.033" rpy="0 0 0"/>
      <geometry>
        <box size="0.11 0.085 0.004"/>
      </geometry>
    </collision>
    <visual>
      <origin xyz="-0.048 0 -0.0245" rpy="-1.57 0 0"/>
      <geometry>
        <cylinder radius="0.008" length="0.03"/>
      </geometry>
    </visual>
    <collision>
      <origin xyz="-0.048 0 -0.0245" rpy="-1.57 0 0"/>
      <geometry>
        <cylinder radius="0.008" length="0.03"/>
      </geometry>
    </collision>
    <visual>
      <origin xyz="-0.048 0.000012 -0.0395" rpy="-1.57 0 0"/>
      <geometry>
        <sphere radius="0.008"/>
      </geometry>
    </visual>
    <collision>
      <origin xyz="-0.048 0.000012 -0.0395" rpy="-1.57 0 0"/>
      <geometry>
        <sphere radius="0.008"/>
      </geometry>
    </collision>
    <visual>
      <origin xyz="-0.048 -0.000012 -0.0095" rpy="-1.57 0 0"/>
      <geometry>
        <sphere radius="0.008"/>
      </geometry>
    </visual>
    <collision>
      <origin xyz="-0.048 -0.000012 -0.0095" rpy="-1.57 0 0"/>
      <geometry>
        <sphere radius="0.008"/>
      </geometry>
    </collision>
    <visual>
      <origin xyz="0.065 0.005 -0.027" rpy="0 0 0"/>
      <geometry>
        <box size="0.04 0.085 0.016"/>
      </geometry>
    </visual>
    <collision>
      <origin xyz="0.065 0.005 -0.027" rpy="0 0 0"/>
      <geometry>
        <box size="0.04 0.085 0.016"/>
      </geometry>
    </collision>
  </link>
  <link name="LFoot/Bumper/Right">
    <visual>
      <origin xyz="0.0075 0 0" rpy="0 0 0"/>
      <geometry>
        <box size="0.005 0.025 0.01"/>
      </geometry>
    </visual>
    <collision>
      <origin xyz="0.0075 0 0" rpy="0 0 0"/>
      <geometry>
        <box size="0.005 0.025 0.01"/>
      </geometry>
    </collision>
  </link>
  <joint name="solid_3_LFoot/Bumper/Right_joint" type="fixed">
    <parent link="solid_3"/>
    <child link="LFoot/Bumper/Right"/>
    <origin xyz="0.09 -0.012 -0.023" rpy="0 0 0"/>
  </joint>
  <link name="LFoot/Bumper/Left">
    <visual>
      <origin xyz="0.0075 0 0" rpy="0 0 0"/>
      <geometry>
        <box size="0.005 0.025 0.01"/>
      </geometry>
    </visual>
    <collision>
      <origin xyz="0.0075 0 0" rpy="0 0 0"/>
      <geometry>
        <box size="0.005 0.025 0.01"/>
      </geometry>
    </collision>
  </link>
  <joint name="solid_3_LFoot/Bumper/Left_joint" type="fixed">
    <parent link="solid_3"/>
    <child link="LFoot/Bumper/Left"/>
    <origin xyz="0.09 0.022 -0.023" rpy="0 0 0"/>
  </joint>
  <link name="LFoot/Led">
  </link>
  <joint name="solid_3_LFoot/Led_joint" type="fixed">
    <parent link="solid_3"/>
    <child link="LFoot/Led"/>
    <origin xyz="0 0 0" rpy="0 0 0"/>
  </joint>
  <link name="LFsr">
  </link>
  <joint name="solid_3_LFsr_joint" type="fixed">
    <parent link="solid_3"/>
    <child link="LFsr"/>
    <origin xyz="0.02 0.007 -0.040939" rpy="0 0 -3.141585"/>
  </joint>
  <joint name="RHipYawPitch" type="revolute">
    <parent link="base_link"/>
    <child link="RHip"/>
    <axis xyz="0 0.707107 0.707107"/>
    <limit effort="14.8" lower="-1.14529" upper="0.740718" velocity="4.16174"/>
    <origin xyz="0 -0.05 -0.085" rpy="0 -0.000001 -0.000001"/>
  </joint>
  <link name="RHip">
  </link>
  <joint name="RHipRoll" type="revolute">
    <parent link="RHip"/>
    <child link="solid_4"/>
    <axis xyz="1 0 0"/>
    <limit effort="14.8" lower="-0.738274" upper="0.449597" velocity="4.16174"/>
    <origin xyz="0 0 0" rpy="0 0 0"/>
  </joint>
  <link name="solid_4">
    <visual>
      <origin xyz="-0.017 0 0.004" rpy="0 0 0"/>
      <geometry>
        <box size="0.025 0.025 0.074"/>
      </geometry>
    </visual>
    <collision>
      <origin xyz="-0.017 0 0.004" rpy="0 0 0"/>
      <geometry>
        <box size="0.025 0.025 0.074"/>
      </geometry>
    </collision>
    <visual>
      <origin xyz="-0.018 0 0" rpy="0 0 0"/>
      <geometry>
        <box size="0.08 0.025 0.025"/>
      </geometry>
    </visual>
    <collision>
      <origin xyz="-0.018 0 0" rpy="0 0 0"/>
      <geometry>
        <box size="0.08 0.025 0.025"/>
      </geometry>
    </collision>
  </link>
  <joint name="RHipPitch" type="revolute">
    <parent link="solid_4"/>
    <child link="solid_5"/>
    <axis xyz="0 1 0"/>
    <limit effort="9.8" lower="-1.77378" upper="0.48398" velocity="6.40239"/>
    <origin xyz="0 0 0" rpy="0 0 0"/>
  </joint>
  <link name="solid_5">
    <visual>
      <origin xyz="-0.009 0 -0.015" rpy="1.570803 -1.047198 -0.000004"/>
      <geometry>
        <cylinder radius="0.03" length="0.01"/>
      </geometry>
    </visual>
    <collision>
      <origin xyz="-0.009 0 -0.015" rpy="1.570803 -1.047198 -0.000004"/>
      <geometry>
        <cylinder radius="0.03" length="0.01"/>
      </geometry>
    </collision>
    <visual>
      <origin xyz="-0.01333 0 -0.0125" rpy="1.570803 -1.047198 -0.000004"/>
      <geometry>
        <sphere radius="0.03"/>
      </geometry>
    </visual>
    <collision>
      <origin xyz="-0.01333 0 -0.0125" rpy="1.570803 -1.047198 -0.000004"/>
      <geometry>
        <sphere radius="0.03"/>
      </geometry>
    </collision>
    <visual>
      <origin xyz="-0.00467 0 -0.0175" rpy="1.570803 -1.047198 -0.000004"/>
      <geometry>
        <sphere radius="0.03"/>
      </geometry>
    </visual>
    <collision>
      <origin xyz="-0.00467 0 -0.0175" rpy="1.570803 -1.047198 -0.000004"/>
      <geometry>
        <sphere radius="0.03"/>
      </geometry>
    </collision>
    <visual>
      <origin xyz="0.008 0 -0.066261" rpy="0 -0.383185 0"/>
      <geometry>
        <cylinder radius="0.035" length="0.1"/>
      </geometry>
    </visual>
    <collision>
      <origin xyz="0.008 0 -0.066261" rpy="0 -0.383185 0"/>
      <geometry>
        <cylinder radius="0.035" length="0.1"/>
      </geometry>
    </collision>
  </link>
  <joint name="RKneePitch" type="revolute">
    <parent link="solid_5"/>
    <child link="solid_6"/>
    <axis xyz="0 1 0"/>
    <limit effort="9.8" lower="-0.0923279" upper="2.11255" velocity="6.40239"/>
    <origin xyz="0 0 -0.1" rpy="0 -0.000001 0"/>
  </joint>
  <link name="solid_6">
    <visual>
      <origin xyz="0.01 0 -0.033" rpy="0 0.462 0"/>
      <geometry>
        <box size="0.04 0.08 0.07"/>
      </geometry>
    </visual>
    <collision>
      <origin xyz="0.01 0 -0.033" rpy="0 0.462 0"/>
      <geometry>
        <box size="0.04 0.08 0.07"/>
      </geometry>
    </collision>
    <visual>
      <origin xyz="0 -0.003 -0.09" rpy="1.57 0 0"/>
      <geometry>
        <cylinder radius="0.035" length="0.018"/>
      </geometry>
    </visual>
    <collision>
      <origin xyz="0 -0.003 -0.09" rpy="1.57 0 0"/>
      <geometry>
        <cylinder radius="0.035" length="0.018"/>
      </geometry>
    </collision>
    <visual>
      <origin xyz="0 -0.002993 -0.081" rpy="1.57 0 0"/>
      <geometry>
        <sphere radius="0.035"/>
      </geometry>
    </visual>
    <collision>
      <origin xyz="0 -0.002993 -0.081" rpy="1.57 0 0"/>
      <geometry>
        <sphere radius="0.035"/>
      </geometry>
    </collision>
    <visual>
      <origin xyz="0 -0.003007 -0.099" rpy="1.57 0 0"/>
      <geometry>
        <sphere radius="0.035"/>
      </geometry>
    </visual>
    <collision>
      <origin xyz="0 -0.003007 -0.099" rpy="1.57 0 0"/>
      <geometry>
        <sphere radius="0.035"/>
      </geometry>
    </collision>
  </link>
  <joint name="RAnklePitch" type="revolute">
    <parent link="solid_6"/>
    <child link="solid_7"/>
    <axis xyz="0 1 0"/>
    <limit effort="9.8" lower="-1.1863" upper="0.932006" velocity="6.40239"/>
    <origin xyz="0 0 -0.1029" rpy="0 -0.000001 0"/>
  </joint>
  <link name="solid_7">
  </link>
  <joint name="RAnkleRoll" type="revolute">
    <parent link="solid_7"/>
    <child link="solid_8"/>
    <axis xyz="1 0 0"/>
    <limit effort="14.8" lower="-0.768992" upper="0.397935" velocity="4.16174"/>
    <origin xyz="0 0 0" rpy="0 0 0"/>
  </joint>
  <link name="solid_8">
    <visual>
      <origin xyz="0.015 -0.007 -0.033" rpy="0 0 0"/>
      <geometry>
        <box size="0.11 0.085 0.004"/>
      </geometry>
    </visual>
    <collision>
      <origin xyz="0.015 -0.007 -0.033" rpy="0 0 0"/>
      <geometry>
        <box size="0.11 0.085 0.004"/>
      </geometry>
    </collision>
    <visual>
      <origin xyz="-0.048 0 -0.0245" rpy="-1.57 0 0"/>
      <geometry>
        <cylinder radius="0.008" length="0.03"/>
      </geometry>
    </visual>
    <collision>
      <origin xyz="-0.048 0 -0.0245" rpy="-1.57 0 0"/>
      <geometry>
        <cylinder radius="0.008" length="0.03"/>
      </geometry>
    </collision>
    <visual>
      <origin xyz="-0.048 0.000012 -0.0395" rpy="-1.57 0 0"/>
      <geometry>
        <sphere radius="0.008"/>
      </geometry>
    </visual>
    <collision>
      <origin xyz="-0.048 0.000012 -0.0395" rpy="-1.57 0 0"/>
      <geometry>
        <sphere radius="0.008"/>
      </geometry>
    </collision>
    <visual>
      <origin xyz="-0.048 -0.000012 -0.0095" rpy="-1.57 0 0"/>
      <geometry>
        <sphere radius="0.008"/>
      </geometry>
    </visual>
    <collision>
      <origin xyz="-0.048 -0.000012 -0.0095" rpy="-1.57 0 0"/>
      <geometry>
        <sphere radius="0.008"/>
      </geometry>
    </collision>
    <visual>
      <origin xyz="0.065 -0.005 -0.027" rpy="0 0 0"/>
      <geometry>
        <box size="0.04 0.085 0.016"/>
      </geometry>
    </visual>
    <collision>
      <origin xyz="0.065 -0.005 -0.027" rpy="0 0 0"/>
      <geometry>
        <box size="0.04 0.085 0.016"/>
      </geometry>
    </collision>
  </link>
  <link name="RFoot/Bumper/Left">
    <visual>
      <origin xyz="0.0075 0 0" rpy="0 0 0"/>
      <geometry>
        <box size="0.005 0.025 0.01"/>
      </geometry>
    </visual>
    <collision>
      <origin xyz="0.0075 0 0" rpy="0 0 0"/>
      <geometry>
        <box size="0.005 0.025 0.01"/>
      </geometry>
    </collision>
  </link>
  <joint name="solid_8_RFoot/Bumper/Left_joint" type="fixed">
    <parent link="solid_8"/>
    <child link="RFoot/Bumper/Left"/>
    <origin xyz="0.09 0.012 -0.023" rpy="0 0 0"/>
  </joint>
  <link name="RFoot/Bumper/Right">
    <visual>
      <origin xyz="0.0075 0 0" rpy="0 0 0"/>
      <geometry>
        <box size="0.005 0.025 0.01"/>
      </geometry>
    </visual>
    <collision>
      <origin xyz="0.0075 0 0" rpy="0 0 0"/>
      <geometry>
        <box size="0.005 0.025 0.01"/>
      </geometry>
    </collision>
  </link>
  <joint name="solid_8_RFoot/Bumper/Right_joint" type="fixed">
    <parent link="solid_8"/>
    <child link="RFoot/Bumper/Right"/>
    <origin xyz="0.09 -0.022 -0.023" rpy="0 0 0"/>
  </joint>
  <link name="RFoot/Led">
  </link>
  <joint name="solid_8_RFoot/Led_joint" type="fixed">
    <parent link="solid_8"/>
    <child link="RFoot/Led"/>
    <origin xyz="0 0 0" rpy="0 0 0"/>
  </joint>
  <link name="RFsr">
  </link>
  <joint name="solid_8_RFsr_joint" type="fixed">
    <parent link="solid_8"/>
    <child link="RFsr"/>
    <origin xyz="0.02 -0.007 -0.040939" rpy="0 0 -3.141585"/>
  </joint>
  <link name="Sonar/Left">
  </link>
  <joint name="base_link_Sonar/Left_joint" type="fixed">
    <parent link="base_link"/>
    <child link="Sonar/Left"/>
    <origin xyz="0.0477 0.0416 0.0509" rpy="0.112752 0.23678 0.449726"/>
  </joint>
  <link name="Sonar/Right">
  </link>
  <joint name="base_link_Sonar/Right_joint" type="fixed">
    <parent link="base_link"/>
    <child link="Sonar/Right"/>
    <origin xyz="0.0477 -0.0416 0.0509" rpy="-0.112752 0.23678 -0.449726"/>
  </joint>
  <link name="inertial unit">
  </link>
  <joint name="base_link_inertial unit_joint" type="fixed">
    <parent link="base_link"/>
    <child link="inertial unit"/>
    <origin xyz="-0.008 0.006 0.029" rpy="1.5708 0 0"/>
  </joint>
  <link name="gyro">
  </link>
  <joint name="base_link_gyro_joint" type="fixed">
    <parent link="base_link"/>
    <child link="gyro"/>
    <origin xyz="-0.008 0.006 0.029" rpy="0 0 0"/>
  </joint>
  <link name="accelerometer">
  </link>
  <joint name="base_link_accelerometer_joint" type="fixed">
    <parent link="base_link"/>
    <child link="accelerometer"/>
    <origin xyz="-0.008 0.00606 0.027" rpy="3.14159 0 0"/>
  </joint>
  <link name="super_emitter">
  </link>
  <joint name="base_link_super_emitter_joint" type="fixed">
    <parent link="base_link"/>
    <child link="super_emitter"/>
    <origin xyz="0 0 0" rpy="0 0 0"/>
  </joint>
  <link name="emitter">
  </link>
  <joint name="base_link_emitter_joint" type="fixed">
    <parent link="base_link"/>
    <child link="emitter"/>
    <origin xyz="0 0 0" rpy="0 0 0"/>
  </joint>
  <link name="receiver">
  </link>
  <joint name="base_link_receiver_joint" type="fixed">
    <parent link="base_link"/>
    <child link="receiver"/>
    <origin xyz="0 0 0" rpy="0 0 0"/>
  </joint>
  <link name="gps">
  </link>
  <joint name="base_link_gps_joint" type="fixed">
    <parent link="base_link"/>
    <child link="gps"/>
    <origin xyz="0 0 0" rpy="0 0 0"/>
  </joint>
  <link name="ChestBoard/Led">
  </link>
  <joint name="base_link_ChestBoard/Led_joint" type="fixed">
    <parent link="base_link"/>
    <child link="ChestBoard/Led"/>
    <origin xyz="0.053 0 0.058" rpy="0 0 0"/>
  </joint>

  <!-- HEAD -->
  <link name="neck_link"/>
  <joint name="HeadYaw" type="revolute">
    <parent link="base_link"/>
    <child link="neck_link"/>
    <axis xyz="0 0 1"/>
    <limit effort="3.3" lower="-2.0857" upper="2.0857" velocity="8.26797"/>
    <origin xyz="0 0 0.1265" rpy="0 0 0"/>
  </joint>
  <link name="head_link"/>
  <joint name="HeadPitch" type="revolute">
    <parent link="neck_link"/>
    <child link="head_link"/>
    <axis xyz="0 1 0"/>
    <limit effort="3.3" lower="-0.6720" upper="0.5149" velocity="7.19407"/>
    <origin xyz="0 0 0" rpy="0 0 0"/>
  </joint>

  <!-- LEFT ARM -->
  <link name="LShoulder1_link"/>
  <joint name="LShoulderPitch" type="revolute">
    <parent link="base_link"/>
    <child link="LShoulder1_link"/>
    <axis xyz="0 1 0"/>
    <limit effort="3.3" lower="-2.0857" upper="2.0857" velocity="8.26797"/>
    <origin xyz="0 0.098 0.1" rpy="0 0 0"/>
  </joint>
  <link name="LShoulder_link"/>
  <joint name="LShoulderRoll" type="revolute">
    <parent link="LShoulder1_link"/>
    <child link="LShoulder_link"/>
    <axis xyz="0 0 1"/>
    <limit effort="3.3" lower="-0.3142" upper="1.3265" velocity="7.19407"/>
    <origin xyz="0 0 0" rpy="0 0 0"/>
  </joint>
  <link name="LElbow_link"/>
  <joint name="LElbowYaw" type="revolute">
    <parent link="LShoulder_link"/>
    <child link="LElbow_link"/>
    <axis xyz="1 0 0"/>
    <limit effort="4.0" lower="-2.0857" upper="2.0857" velocity="8.26797"/>
    <origin xyz="0.105 0.015 0" rpy="0 0 0"/>
  </joint>
  <link name="LForearm_link"/>
  <joint name="LElbowRoll" type="revolute">
    <parent link="LElbow_link"/>
    <child link="LForearm_link"/>
    <axis xyz="0 0 1"/>
    <limit effort="5.0" lower="-1.5446" upper="0.0" velocity="7.19407"/>
    <origin xyz="0 0 0" rpy="0 0 0"/>
  </joint>
  <link name="LHand_link"/>
  <joint name="LWristYaw" type="revolute">
    <parent link="LForearm_link"/>
    <child link="LHand_link"/>
    <axis xyz="1 0 0"/>
    <limit effort="1.5" lower="-1.8239" upper="1.8239" velocity="24.6229"/>
    <origin xyz="0.05595 0 0" rpy="0 0 0"/>
  </joint>

  <!-- RIGHT ARM -->
  <link name="RShoulder1_link"/>
  <joint name="RShoulderPitch" type="revolute">
    <parent link="base_link"/>
    <child link="RShoulder1_link"/>
    <axis xyz="0 1 0"/>
    <limit effort="3.3" lower="-2.0857" upper="2.0857" velocity="8.26797"/>
    <origin xyz="0 -0.098 0.1" rpy="0 0 0"/>
  </joint>
  <link name="RShoulder_link"/>
  <joint name="RShoulderRoll" type="revolute">
    <parent link="RShoulder1_link"/>
    <child link="RShoulder_link"/>
    <axis xyz="0 0 1"/>
    <limit effort="3.3" lower="-1.3265" upper="0.3142" velocity="7.19407"/>
    <origin xyz="0 0 0" rpy="0 0 0"/>
  </joint>
  <link name="RElbow_link"/>
  <joint name="RElbowYaw" type="revolute">
    <parent link="RShoulder_link"/>
    <child link="RElbow_link"/>
    <axis xyz="1 0 0"/>
    <limit effort="4.0" lower="-2.0857" upper="2.0857" velocity="8.26797"/>
    <origin xyz="0.105 -0.015 0" rpy="0 0 0"/>
  </joint>
  <link name="RForearm_link"/>
  <joint name="RElbowRoll" type="revolute">
    <parent link="RElbow_link"/>
    <child link="RForearm_link"/>
    <axis xyz="0 0 1"/>
    <limit effort="5.0" lower="0.0" upper="1.5446" velocity="7.19407"/>
    <origin xyz="0 0 0" rpy="0 0 0"/>
  </joint>
  <link name="RHand_link"/>
  <joint name="RWristYaw" type="revolute">
    <parent link="RForearm_link"/>
    <child link="RHand_link"/>
    <axis xyz="1 0 0"/>
    <limit effort="1.5" lower="-1.8239" upper="1.8239" velocity="24.6229"/>
    <origin xyz="0.05595 0 0" rpy="0 0 0"/>
  </joint>
</robot>
